2019-03-22 12:12:37,773 ERROR: Exception on /upload [POST] [in /home/kazeem/cirex/cirexenv/lib/python3.7/site-packages/flask/app.py:1761]
Traceback (most recent call last):
  File "/home/kazeem/cirex/cirexenv/lib/python3.7/site-packages/sqlalchemy/engine/base.py", line 1193, in _execute_context
    context)
  File "/home/kazeem/cirex/cirexenv/lib/python3.7/site-packages/sqlalchemy/engine/default.py", line 509, in do_execute
    cursor.execute(statement, parameters)
  File "/home/kazeem/cirex/cirexenv/lib/python3.7/site-packages/MySQLdb/cursors.py", line 250, in execute
    self.errorhandler(self, exc, value)
  File "/home/kazeem/cirex/cirexenv/lib/python3.7/site-packages/MySQLdb/connections.py", line 50, in defaulterrorhandler
    raise errorvalue
  File "/home/kazeem/cirex/cirexenv/lib/python3.7/site-packages/MySQLdb/cursors.py", line 247, in execute
    res = self._query(query)
  File "/home/kazeem/cirex/cirexenv/lib/python3.7/site-packages/MySQLdb/cursors.py", line 412, in _query
    rowcount = self._do_query(q)
  File "/home/kazeem/cirex/cirexenv/lib/python3.7/site-packages/MySQLdb/cursors.py", line 375, in _do_query
    db.query(q)
  File "/home/kazeem/cirex/cirexenv/lib/python3.7/site-packages/MySQLdb/connections.py", line 276, in query
    _mysql.connection.query(self, query)
_mysql_exceptions.IntegrityError: (1062, "Duplicate entry 'test' for key 'ix_search_name'")

The above exception was the direct cause of the following exception:

Traceback (most recent call last):
  File "/home/kazeem/cirex/cirexenv/lib/python3.7/site-packages/flask/app.py", line 2292, in wsgi_app
    response = self.full_dispatch_request()
  File "/home/kazeem/cirex/cirexenv/lib/python3.7/site-packages/flask/app.py", line 1815, in full_dispatch_request
    rv = self.handle_user_exception(e)
  File "/home/kazeem/cirex/cirexenv/lib/python3.7/site-packages/flask/app.py", line 1718, in handle_user_exception
    reraise(exc_type, exc_value, tb)
  File "/home/kazeem/cirex/cirexenv/lib/python3.7/site-packages/flask/_compat.py", line 35, in reraise
    raise value
  File "/home/kazeem/cirex/cirexenv/lib/python3.7/site-packages/flask/app.py", line 1813, in full_dispatch_request
    rv = self.dispatch_request()
  File "/home/kazeem/cirex/cirexenv/lib/python3.7/site-packages/flask/app.py", line 1799, in dispatch_request
    return self.view_functions[rule.endpoint](**req.view_args)
  File "/home/kazeem/cirex/cirex/main/views.py", line 52, in upload
    db.session.commit()
  File "/home/kazeem/cirex/cirexenv/lib/python3.7/site-packages/sqlalchemy/orm/scoping.py", line 153, in do
    return getattr(self.registry(), name)(*args, **kwargs)
  File "/home/kazeem/cirex/cirexenv/lib/python3.7/site-packages/sqlalchemy/orm/session.py", line 943, in commit
    self.transaction.commit()
  File "/home/kazeem/cirex/cirexenv/lib/python3.7/site-packages/sqlalchemy/orm/session.py", line 467, in commit
    self._prepare_impl()
  File "/home/kazeem/cirex/cirexenv/lib/python3.7/site-packages/sqlalchemy/orm/session.py", line 447, in _prepare_impl
    self.session.flush()
  File "/home/kazeem/cirex/cirexenv/lib/python3.7/site-packages/sqlalchemy/orm/session.py", line 2254, in flush
    self._flush(objects)
  File "/home/kazeem/cirex/cirexenv/lib/python3.7/site-packages/sqlalchemy/orm/session.py", line 2380, in _flush
    transaction.rollback(_capture_exception=True)
  File "/home/kazeem/cirex/cirexenv/lib/python3.7/site-packages/sqlalchemy/util/langhelpers.py", line 66, in __exit__
    compat.reraise(exc_type, exc_value, exc_tb)
  File "/home/kazeem/cirex/cirexenv/lib/python3.7/site-packages/sqlalchemy/util/compat.py", line 249, in reraise
    raise value
  File "/home/kazeem/cirex/cirexenv/lib/python3.7/site-packages/sqlalchemy/orm/session.py", line 2344, in _flush
    flush_context.execute()
  File "/home/kazeem/cirex/cirexenv/lib/python3.7/site-packages/sqlalchemy/orm/unitofwork.py", line 391, in execute
    rec.execute(self)
  File "/home/kazeem/cirex/cirexenv/lib/python3.7/site-packages/sqlalchemy/orm/unitofwork.py", line 556, in execute
    uow
  File "/home/kazeem/cirex/cirexenv/lib/python3.7/site-packages/sqlalchemy/orm/persistence.py", line 181, in save_obj
    mapper, table, insert)
  File "/home/kazeem/cirex/cirexenv/lib/python3.7/site-packages/sqlalchemy/orm/persistence.py", line 866, in _emit_insert_statements
    execute(statement, params)
  File "/home/kazeem/cirex/cirexenv/lib/python3.7/site-packages/sqlalchemy/engine/base.py", line 948, in execute
    return meth(self, multiparams, params)
  File "/home/kazeem/cirex/cirexenv/lib/python3.7/site-packages/sqlalchemy/sql/elements.py", line 269, in _execute_on_connection
    return connection._execute_clauseelement(self, multiparams, params)
  File "/home/kazeem/cirex/cirexenv/lib/python3.7/site-packages/sqlalchemy/engine/base.py", line 1060, in _execute_clauseelement
    compiled_sql, distilled_params
  File "/home/kazeem/cirex/cirexenv/lib/python3.7/site-packages/sqlalchemy/engine/base.py", line 1200, in _execute_context
    context)
  File "/home/kazeem/cirex/cirexenv/lib/python3.7/site-packages/sqlalchemy/engine/base.py", line 1413, in _handle_dbapi_exception
    exc_info
  File "/home/kazeem/cirex/cirexenv/lib/python3.7/site-packages/sqlalchemy/util/compat.py", line 265, in raise_from_cause
    reraise(type(exception), exception, tb=exc_tb, cause=cause)
  File "/home/kazeem/cirex/cirexenv/lib/python3.7/site-packages/sqlalchemy/util/compat.py", line 248, in reraise
    raise value.with_traceback(tb)
  File "/home/kazeem/cirex/cirexenv/lib/python3.7/site-packages/sqlalchemy/engine/base.py", line 1193, in _execute_context
    context)
  File "/home/kazeem/cirex/cirexenv/lib/python3.7/site-packages/sqlalchemy/engine/default.py", line 509, in do_execute
    cursor.execute(statement, parameters)
  File "/home/kazeem/cirex/cirexenv/lib/python3.7/site-packages/MySQLdb/cursors.py", line 250, in execute
    self.errorhandler(self, exc, value)
  File "/home/kazeem/cirex/cirexenv/lib/python3.7/site-packages/MySQLdb/connections.py", line 50, in defaulterrorhandler
    raise errorvalue
  File "/home/kazeem/cirex/cirexenv/lib/python3.7/site-packages/MySQLdb/cursors.py", line 247, in execute
    res = self._query(query)
  File "/home/kazeem/cirex/cirexenv/lib/python3.7/site-packages/MySQLdb/cursors.py", line 412, in _query
    rowcount = self._do_query(q)
  File "/home/kazeem/cirex/cirexenv/lib/python3.7/site-packages/MySQLdb/cursors.py", line 375, in _do_query
    db.query(q)
  File "/home/kazeem/cirex/cirexenv/lib/python3.7/site-packages/MySQLdb/connections.py", line 276, in query
    _mysql.connection.query(self, query)
sqlalchemy.exc.IntegrityError: (_mysql_exceptions.IntegrityError) (1062, "Duplicate entry 'test' for key 'ix_search_name'") [SQL: 'INSERT INTO search (name, citation_list, search_string) VALUES (%s, %s, %s)'] [parameters: ('test', b'17990196\r\n19439099\r\n11748599\r\n15187799\r\n21199975\r\n17135993\r\n21813428\r\n20855048\r\n18945398\r\n11068889\r\n16858633\r\n29461920\r\n20684019\r\n17667483', None)] (Background on this error at: http://sqlalche.me/e/gkpj)
